Workbook

Sheet Read Me
A1: Logistics Shipment MIS & Document Verification Tracker
A2: Excel project for an MIS Executive role. All names, clients, rates, dates and amounts are fictional sample data.
A4: Sheets in this workbook
A5: Sheet | B5: What it does | C5: Excel skills shown
A6: Dashboard | B6: KPI cards, 4 charts and the tables behind them. Updates automatically. | C6: COUNTIFS, SUMIFS, charts, TEXT, DATE
A7: MIS Report | B7: Choose Daily, Weekly or Monthly and a date; all numbers rebuild for that period. | C7: Dropdown, SUMIFS / COUNTIFS / AVERAGEIFS, date logic
A8: Shipment Data | B8: Main data entry sheet: one row per shipment, with auto lookups and a Data Check per row. | C8: VLOOKUP, INDEX-MATCH, IF, Data Validation, Conditional Formatting
A9: Doc Verification | B9: Tracker for client and candidate documents: status, remark, aging and completeness check. | C9: Dropdowns, IF, COUNTIF, aging with TODAY, Conditional Formatting
A10: Data Quality | B10: Counts every type of data error and shows accuracy % and error rate %. | C10: COUNTIF, accuracy KPI
A11: Masters | B11: Rate card, client list, dropdown lists and settings (SLA days). | C11: Lookup tables, named lists
A13: How to use
A14: 1 | B14: Add shipments on Shipment Data (blue columns only). Copy the grey formula cells down for new rows.
A15: 2 | B15: Check the Data Check column (Q). Filter for anything that is not OK and fix it at the source. Only OK rows enter reports.
A16: 3 | B16: On MIS Report, pick the Report Type and Report Date (yellow cells).
A17: 4 | B17: Update document Status on Doc Verification using the dropdown. Add a remark for every Discrepancy.
A18: 5 | B18: Open Dashboard for the overall picture.
A20: Colour legend
A21: Blue text | B21: Input cell. You type or edit these.
A22: Black text, grey fill | B22: Formula. Do not overwrite.
A23: Yellow fill | B23: Selector cell (report type / date).
A24: Red row | B24: Data Check found a problem in that row.
A26: Assumptions and notes
A27: Sample data | B27: 300 fictional shipments (Apr-Sep 2026) and 120 fictional documents. Some errors were added on purpose (duplicate IDs, blanks, wrong dates, missing remarks) so the checks have something to catch.
A28: Rates and TAT | B28: Rate per kg and standard delivery days per route are made-up values on Masters. Promised Delivery = Ship Date + TAT. Freight = Weight x Rate.
A29: On-time rule | B29: A delivered shipment is On-Time if Actual Delivery <= Promised Delivery.
A30: Verification SLA | B30: 7 days (Masters B20). A Pending document older than this is Overdue.
A31: Lookups | B31: Origin, Destination and TAT use VLOOKUP; Rate uses INDEX-MATCH. XLOOKUP can replace either in Excel 2021 / 365.
A32: Formula range | B32: Report formulas read up to row 1000 (shipments) and row 500 (documents).
A34: Optional next steps (do these in Excel)
A35: PivotTable | B35: Select Shipment Data > Insert > PivotTable. Rows: Client, Columns: Month, Values: Sum of Freight Amount. Filter Data Check = OK.
A36: Power Query | B36: Data > Get Data > From File > From Folder to combine monthly shipment files into one table.

Sheet Dashboard
A1: Logistics Shipment MIS & Document Verification Dashboard
A2: Auto-updates from Shipment Data and Doc Verification. Shipment figures use only records that pass the Data Check.
A4: Total Shipments (clean) | B4: Total Freight (Rs) | C4: On-Time Delivery % | D4: Shipment Data Accuracy | E4: Docs Verified % | F4: Pending Docs | G4: Overdue Pending Docs | H4: Docs with Discrepancy
A5: =COUNTIF('Shipment Data'!$Q$2:$Q$1000,"OK") -> 279 | B5: =SUMIFS('Shipment Data'!$I$2:$I$1000,'Shipment Data'!$Q$2:$Q$1000,"OK") -> 7992228 | C5: =IF(COUNTIFS('Shipment Data'!$Q$2:$Q$1000,"OK",'Shipment Data'!$O$2:$O$1000,"Yes")+COUNTIFS('Shipment Data'!$Q$2:$Q$1000,"OK",'Shipment Data'!$O$2:$O$1000,"No")=0,"n/a",COUNTIFS('Shipment Data'!$Q$2:$Q$1000,"OK",'Shipment Data'!$O$2:$O$1000,"Yes")/(COUNTIFS('Shipment Data'!$Q$2:$Q$1000,"OK",'Shipment Data'!$O$2:$O$1000,"Yes")+COUNTIFS('Shipment Data'!$Q$2:$Q$1000,"OK",'Shipment Data'!$O$2:$O$1000,"No"))) -> 0.65441176 | D5: ='Data Quality'!B13 -> 0.93 | E5: =IF(COUNTA('Doc Verification'!$A$2:$A$500)=0,0,COUNTIF('Doc Verification'!$G$2:$G$500,"Verified")/COUNTA('Doc Verification'!$A$2:$A$500)) -> 0.70833333 | F5: =COUNTIF('Doc Verification'!$G$2:$G$500,"Pending") -> 27 | G5: =COUNTIF('Doc Verification'!$L$2:$L$500,"Overdue") -> 13 | H5: =COUNTIF('Doc Verification'!$G$2:$G$500,"Discrepancy") -> 8
A40: Data behind the charts
A41: Monthly trend | G41: Document status
A42: Month | B42: Month Start | C42: Shipments | D42: Freight (Rs) | E42: On-Time % | G42: Status | H42: Count | I42: Share
A43: =TEXT(B43,"mmm yyyy") -> Apr 2026 | B43: 46113 | C43: =COUNTIFS('Shipment Data'!$P$2:$P$1000,$B43,'Shipment Data'!$Q$2:$Q$1000,"OK") -> 23 | D43: =SUMIFS('Shipment Data'!$I$2:$I$1000,'Shipment Data'!$P$2:$P$1000,$B43,'Shipment Data'!$Q$2:$Q$1000,"OK") -> 581753 | E43: =IF(COUNTIFS('Shipment Data'!$P$2:$P$1000,$B43,'Shipment Data'!$Q$2:$Q$1000,"OK",'Shipment Data'!$O$2:$O$1000,"Yes")+COUNTIFS('Shipment Data'!$P$2:$P$1000,$B43,'Shipment Data'!$Q$2:$Q$1000,"OK",'Shipment Data'!$O$2:$O$1000,"No")=0,0,COUNTIFS('Shipment Data'!$P$2:$P$1000,$B43,'Shipment Data'!$Q$2:$Q$1000,"OK",'Shipment Data'!$O$2:$O$1000,"Yes")/(COUNTIFS('Shipment Data'!$P$2:$P$1000,$B43,'Shipment Data'!$Q$2:$Q$1000,"OK",'Shipment Data'!$O$2:$O$1000,"Yes")+COUNTIFS('Shipment Data'!$P$2:$P$1000,$B43,'Shipment Data'!$Q$2:$Q$1000,"OK",'Shipment Data'!$O$2:$O$1000,"No"))) -> 0.73913043 | G43: Verified | H43: =COUNTIF('Doc Verification'!$G$2:$G$500,G43) -> 85 | I43: =IF($H$46=0,0,H43/$H$46) -> 0.70833333
A44: =TEXT(B44,"mmm yyyy") -> May 2026 | B44: =DATE(YEAR(B43),MONTH(B43)+1,1) -> 46143 | C44: =COUNTIFS('Shipment Data'!$P$2:$P$1000,$B44,'Shipment Data'!$Q$2:$Q$1000,"OK") -> 48 | D44: =SUMIFS('Shipment Data'!$I$2:$I$1000,'Shipment Data'!$P$2:$P$1000,$B44,'Shipment Data'!$Q$2:$Q$1000,"OK") -> 1248303 | E44: =IF(COUNTIFS('Shipment Data'!$P$2:$P$1000,$B44,'Shipment Data'!$Q$2:$Q$1000,"OK",'Shipment Data'!$O$2:$O$1000,"Yes")+COUNTIFS('Shipment Data'!$P$2:$P$1000,$B44,'Shipment Data'!$Q$2:$Q$1000,"OK",'Shipment Data'!$O$2:$O$1000,"No")=0,0,COUNTIFS('Shipment Data'!$P$2:$P$1000,$B44,'Shipment Data'!$Q$2:$Q$1000,"OK",'Shipment Data'!$O$2:$O$1000,"Yes")/(COUNTIFS('Shipment Data'!$P$2:$P$1000,$B44,'Shipment Data'!$Q$2:$Q$1000,"OK",'Shipment Data'!$O$2:$O$1000,"Yes")+COUNTIFS('Shipment Data'!$P$2:$P$1000,$B44,'Shipment Data'!$Q$2:$Q$1000,"OK",'Shipment Data'!$O$2:$O$1000,"No"))) -> 0.625 | G44: Pending | H44: =COUNTIF('Doc Verification'!$G$2:$G$500,G44) -> 27 | I44: =IF($H$46=0,0,H44/$H$46) -> 0.225
A45: =TEXT(B45,"mmm yyyy") -> Jun 2026 | B45: =DATE(YEAR(B44),MONTH(B44)+1,1) -> 46174 | C45: =COUNTIFS('Shipment Data'!$P$2:$P$1000,$B45,'Shipment Data'!$Q$2:$Q$1000,"OK") -> 37 | D45: =SUMIFS('Shipment Data'!$I$2:$I$1000,'Shipment Data'!$P$2:$P$1000,$B45,'Shipment Data'!$Q$2:$Q$1000,"OK") -> 1243245 | E45: =IF(COUNTIFS('Shipment Data'!$P$2:$P$1000,$B45,'Shipment Data'!$Q$2:$Q$1000,"OK",'Shipment Data'!$O$2:$O$1000,"Yes")+COUNTIFS('Shipment Data'!$P$2:$P$1000,$B45,'Shipment Data'!$Q$2:$Q$1000,"OK",'Shipment Data'!$O$2:$O$1000,"No")=0,0,COUNTIFS('Shipment Data'!$P$2:$P$1000,$B45,'Shipment Data'!$Q$2:$Q$1000,"OK",'Shipment Data'!$O$2:$O$1000,"Yes")/(COUNTIFS('Shipment Data'!$P$2:$P$1000,$B45,'Shipment Data'!$Q$2:$Q$1000,"OK",'Shipment Data'!$O$2:$O$1000,"Yes")+COUNTIFS('Shipment Data'!$P$2:$P$1000,$B45,'Shipment Data'!$Q$2:$Q$1000,"OK",'Shipment Data'!$O$2:$O$1000,"No"))) -> 0.75675676 | G45: Discrepancy | H45: =COUNTIF('Doc Verification'!$G$2:$G$500,G45) -> 8 | I45: =IF($H$46=0,0,H45/$H$46) -> 0.066666667
A46: =TEXT(B46,"mmm yyyy") -> Jul 2026 | B46: =DATE(YEAR(B45),MONTH(B45)+1,1) -> 46204 | C46: =COUNTIFS('Shipment Data'!$P$2:$P$1000,$B46,'Shipment Data'!$Q$2:$Q$1000,"OK") -> 66 | D46: =SUMIFS('Shipment Data'!$I$2:$I$1000,'Shipment Data'!$P$2:$P$1000,$B46,'Shipment Data'!$Q$2:$Q$1000,"OK") -> 2107927 | E46: =IF(COUNTIFS('Shipment Data'!$P$2:$P$1000,$B46,'Shipment Data'!$Q$2:$Q$1000,"OK",'Shipment Data'!$O$2:$O$1000,"Yes")+COUNTIFS('Shipment Data'!$P$2:$P$1000,$B46,'Shipment Data'!$Q$2:$Q$1000,"OK",'Shipment Data'!$O$2:$O$1000,"No")=0,0,COUNTIFS('Shipment Data'!$P$2:$P$1000,$B46,'Shipment Data'!$Q$2:$Q$1000,"OK",'Shipment Data'!$O$2:$O$1000,"Yes")/(COUNTIFS('Shipment Data'!$P$2:$P$1000,$B46,'Shipment Data'!$Q$2:$Q$1000,"OK",'Shipment Data'!$O$2:$O$1000,"Yes")+COUNTIFS('Shipment Data'!$P$2:$P$1000,$B46,'Shipment Data'!$Q$2:$Q$1000,"OK",'Shipment Data'!$O$2:$O$1000,"No"))) -> 0.56060606 | G46: Total | H46: =SUM(H43:H45) -> 120 | I46: =SUM(I43:I45) -> 1
A47: =TEXT(B47,"mmm yyyy") -> Aug 2026 | B47: =DATE(YEAR(B46),MONTH(B46)+1,1) -> 46235 | C47: =COUNTIFS('Shipment Data'!$P$2:$P$1000,$B47,'Shipment Data'!$Q$2:$Q$1000,"OK") -> 64 | D47: =SUMIFS('Shipment Data'!$I$2:$I$1000,'Shipment Data'!$P$2:$P$1000,$B47,'Shipment Data'!$Q$2:$Q$1000,"OK") -> 1561381 | E47: =IF(COUNTIFS('Shipment Data'!$P$2:$P$1000,$B47,'Shipment Data'!$Q$2:$Q$1000,"OK",'Shipment Data'!$O$2:$O$1000,"Yes")+COUNTIFS('Shipment Data'!$P$2:$P$1000,$B47,'Shipment Data'!$Q$2:$Q$1000,"OK",'Shipment Data'!$O$2:$O$1000,"No")=0,0,COUNTIFS('Shipment Data'!$P$2:$P$1000,$B47,'Shipment Data'!$Q$2:$Q$1000,"OK",'Shipment Data'!$O$2:$O$1000,"Yes")/(COUNTIFS('Shipment Data'!$P$2:$P$1000,$B47,'Shipment Data'!$Q$2:$Q$1000,"OK",'Shipment Data'!$O$2:$O$1000,"Yes")+COUNTIFS('Shipment Data'!$P$2:$P$1000,$B47,'Shipment Data'!$Q$2:$Q$1000,"OK",'Shipment Data'!$O$2:$O$1000,"No"))) -> 0.640625
A48: =TEXT(B48,"mmm yyyy") -> Sep 2026 | B48: =DATE(YEAR(B47),MONTH(B47)+1,1) -> 46266 | C48: =COUNTIFS('Shipment Data'!$P$2:$P$1000,$B48,'Shipment Data'!$Q$2:$Q$1000,"OK") -> 41 | D48: =SUMIFS('Shipment Data'!$I$2:$I$1000,'Shipment Data'!$P$2:$P$1000,$B48,'Shipment Data'!$Q$2:$Q$1000,"OK") -> 1249619 | E48: =IF(COUNTIFS('Shipment Data'!$P$2:$P$1000,$B48,'Shipment Data'!$Q$2:$Q$1000,"OK",'Shipment Data'!$O$2:$O$1000,"Yes")+COUNTIFS('Shipment Data'!$P$2:$P$1000,$B48,'Shipment Data'!$Q$2:$Q$1000,"OK",'Shipment Data'!$O$2:$O$1000,"No")=0,0,COUNTIFS('Shipment Data'!$P$2:$P$1000,$B48,'Shipment Data'!$Q$2:$Q$1000,"OK",'Shipment Data'!$O$2:$O$1000,"Yes")/(COUNTIFS('Shipment Data'!$P$2:$P$1000,$B48,'Shipment Data'!$Q$2:$Q$1000,"OK",'Shipment Data'!$O$2:$O$1000,"Yes")+COUNTIFS('Shipment Data'!$P$2:$P$1000,$B48,'Shipment Data'!$Q$2:$Q$1000,"OK",'Shipment Data'!$O$2:$O$1000,"No"))) -> 0.73529412
A49: Total | C49: =SUM(C43:C48) -> 279 | D49: =SUM(D43:D48) -> 7992228 | E49: =C5 -> 0.65441176
A50: First month (blue) is editable; the other months follow it. Total should match Total Shipments (clean) if all data falls in these 6 months.
A52: Route-wise performance (clean records)
A53: Route Code | B53: Route | C53: Shipments | D53: Freight (Rs) | E53: On-Time %
A54: =Masters!A5 -> DEL-JPR | B54: =Masters!B5&" - "&Masters!C5 -> Delhi - Jaipur | C54: =COUNTIFS('Shipment Data'!$D$2:$D$1000,$A54,'Shipment Data'!$Q$2:$Q$1000,"OK") -> 32 | D54: =SUMIFS('Shipment Data'!$I$2:$I$1000,'Shipment Data'!$D$2:$D$1000,$A54,'Shipment Data'!$Q$2:$Q$1000,"OK") -> 600460 | E54: =IF(COUNTIFS('Shipment Data'!$D$2:$D$1000,$A54,'Shipment Data'!$Q$2:$Q$1000,"OK",'Shipment Data'!$O$2:$O$1000,"Yes")+COUNTIFS('Shipment Data'!$D$2:$D$1000,$A54,'Shipment Data'!$Q$2:$Q$1000,"OK",'Shipment Data'!$O$2:$O$1000,"No")=0,0,COUNTIFS('Shipment Data'!$D$2:$D$1000,$A54,'Shipment Data'!$Q$2:$Q$1000,"OK",'Shipment Data'!$O$2:$O$1000,"Yes")/(COUNTIFS('Shipment Data'!$D$2:$D$1000,$A54,'Shipment Data'!$Q$2:$Q$1000,"OK",'Shipment Data'!$O$2:$O$1000,"Yes")+COUNTIFS('Shipment Data'!$D$2:$D$1000,$A54,'Shipment Data'!$Q$2:$Q$1000,"OK",'Shipment Data'!$O$2:$O$1000,"No"))) -> 0.625
A55: =Masters!A6 -> DEL-LKO | B55: =Masters!B6&" - "&Masters!C6 -> Delhi - Lucknow | C55: =COUNTIFS('Shipment Data'!$D$2:$D$1000,$A55,'Shipment Data'!$Q$2:$Q$1000,"OK") -> 28 | D55: =SUMIFS('Shipment Data'!$I$2:$I$1000,'Shipment Data'!$D$2:$D$1000,$A55,'Shipment Data'!$Q$2:$Q$1000,"OK") -> 661648 | E55: =IF(COUNTIFS('Shipment Data'!$D$2:$D$1000,$A55,'Shipment Data'!$Q$2:$Q$1000,"OK",'Shipment Data'!$O$2:$O$1000,"Yes")+COUNTIFS('Shipment Data'!$D$2:$D$1000,$A55,'Shipment Data'!$Q$2:$Q$1000,"OK",'Shipment Data'!$O$2:$O$1000,"No")=0,0,COUNTIFS('Shipment Data'!$D$2:$D$1000,$A55,'Shipment Data'!$Q$2:$Q$1000,"OK",'Shipment Data'!$O$2:$O$1000,"Yes")/(COUNTIFS('Shipment Data'!$D$2:$D$1000,$A55,'Shipment Data'!$Q$2:$Q$1000,"OK",'Shipment Data'!$O$2:$O$1000,"Yes")+COUNTIFS('Shipment Data'!$D$2:$D$1000,$A55,'Shipment Data'!$Q$2:$Q$1000,"OK",'Shipment Data'!$O$2:$O$1000,"No"))) -> 0.69230769
A56: =Masters!A7 -> DEL-CHD | B56: =Masters!B7&" - "&Masters!C7 -> Delhi - Chandigarh | C56: =COUNTIFS('Shipment Data'!$D$2:$D$1000,$A56,'Shipment Data'!$Q$2:$Q$1000,"OK") -> 24 | D56: =SUMIFS('Shipment Data'!$I$2:$I$1000,'Shipment Data'!$D$2:$D$1000,$A56,'Shipment Data'!$Q$2:$Q$1000,"OK") -> 322350 | E56: =IF(COUNTIFS('Shipment Data'!$D$2:$D$1000,$A56,'Shipment Data'!$Q$2:$Q$1000,"OK",'Shipment Data'!$O$2:$O$1000,"Yes")+COUNTIFS('Shipment Data'!$D$2:$D$1000,$A56,'Shipment Data'!$Q$2:$Q$1000,"OK",'Shipment Data'!$O$2:$O$1000,"No")=0,0,COUNTIFS('Shipment Data'!$D$2:$D$1000,$A56,'Shipment Data'!$Q$2:$Q$1000,"OK",'Shipment Data'!$O$2:$O$1000,"Yes")/(COUNTIFS('Shipment Data'!$D$2:$D$1000,$A56,'Shipment Data'!$Q$2:$Q$1000,"OK",'Shipment Data'!$O$2:$O$1000,"Yes")+COUNTIFS('Shipment Data'!$D$2:$D$1000,$A56,'Shipment Data'!$Q$2:$Q$1000,"OK",'Shipment Data'!$O$2:$O$1000,"No"))) -> 0.70833333
A57: =Masters!A8 -> DEL-AMD | B57: =Masters!B8&" - "&Masters!C8 -> Delhi - Ahmedabad | C57: =COUNTIFS('Shipment Data'!$D$2:$D$1000,$A57,'Shipment Data'!$Q$2:$Q$1000,"OK") -> 20 | D57: =SUMIFS('Shipment Data'!$I$2:$I$1000,'Shipment Data'!$D$2:$D$1000,$A57,'Shipment Data'!$Q$2:$Q$1000,"OK") -> 624975 | E57: =IF(COUNTIFS('Shipment Data'!$D$2:$D$1000,$A57,'Shipment Data'!$Q$2:$Q$1000,"OK",'Shipment Data'!$O$2:$O$1000,"Yes")+COUNTIFS('Shipment Data'!$D$2:$D$1000,$A57,'Shipment Data'!$Q$2:$Q$1000,"OK",'Shipment Data'!$O$2:$O$1000,"No")=0,0,COUNTIFS('Shipment Data'!$D$2:$D$1000,$A57,'Shipment Data'!$Q$2:$Q$1000,"OK",'Shipment Data'!$O$2:$O$1000,"Yes")/(COUNTIFS('Shipment Data'!$D$2:$D$1000,$A57,'Shipment Data'!$Q$2:$Q$1000,"OK",'Shipment Data'!$O$2:$O$1000,"Yes")+COUNTIFS('Shipment Data'!$D$2:$D$1000,$A57,'Shipment Data'!$Q$2:$Q$1000,"OK",'Shipment Data'!$O$2:$O$1000,"No"))) -> 0.65
A58: =Masters!A9 -> DEL-BOM | B58: =Masters!B9&" - "&Masters!C9 -> Delhi - Mumbai | C58: =COUNTIFS('Shipment Data'!$D$2:$D$1000,$A58,'Shipment Data'!$Q$2:$Q$1000,"OK") -> 29 | D58: =SUMIFS('Shipment Data'!$I$2:$I$1000,'Shipment Data'!$D$2:$D$1000,$A58,'Shipment Data'!$Q$2:$Q$1000,"OK") -> 1468700 | E58: =IF(COUNTIFS('Shipment Data'!$D$2:$D$1000,$A58,'Shipment Data'!$Q$2:$Q$1000,"OK",'Shipment Data'!$O$2:$O$1000,"Yes")+COUNTIFS('Shipment Data'!$D$2:$D$1000,$A58,'Shipment Data'!$Q$2:$Q$1000,"OK",'Shipment Data'!$O$2:$O$1000,"No")=0,0,COUNTIFS('Shipment Data'!$D$2:$D$1000,$A58,'Shipment Data'!$Q$2:$Q$1000,"OK",'Shipment Data'!$O$2:$O$1000,"Yes")/(COUNTIFS('Shipment Data'!$D$2:$D$1000,$A58,'Shipment Data'!$Q$2:$Q$1000,"OK",'Shipment Data'!$O$2:$O$1000,"Yes")+COUNTIFS('Shipment Data'!$D$2:$D$1000,$A58,'Shipment Data'!$Q$2:$Q$1000,"OK",'Shipment Data'!$O$2:$O$1000,"No"))) -> 0.64285714
A59: =Masters!A10 -> DEL-CCU | B59: =Masters!B10&" - "&Masters!C10 -> Delhi - Kolkata | C59: =COUNTIFS('Shipment Data'!$D$2:$D$1000,$A59,'Shipment Data'!$Q$2:$Q$1000,"OK") -> 23 | D59: =SUMIFS('Shipment Data'!$I$2:$I$1000,'Shipment Data'!$D$2:$D$1000,$A59,'Shipment Data'!$Q$2:$Q$1000,"OK") -> 1630200 | E59: =IF(COUNTIFS('Shipment Data'!$D$2:$D$1000,$A59,'Shipment Data'!$Q$2:$Q$1000,"OK",'Shipment Data'!$O$2:$O$1000,"Yes")+COUNTIFS('Shipment Data'!$D$2:$D$1000,$A59,'Shipment Data'!$Q$2:$Q$1000,"OK",'Shipment Data'!$O$2:$O$1000,"No")=0,0,COUNTIFS('Shipment Data'!$D$2:$D$1000,$A59,'Shipment Data'!$Q$2:$Q$1000,"OK",'Shipment Data'!$O$2:$O$1000,"Yes")/(COUNTIFS('Shipment Data'!$D$2:$D$1000,$A59,'Shipment Data'!$Q$2:$Q$1000,"OK",'Shipment Data'!$O$2:$O$1000,"Yes")+COUNTIFS('Shipment Data'!$D$2:$D$1000,$A59,'Shipment Data'!$Q$2:$Q$1000,"OK",'Shipment Data'!$O$2:$O$1000,"No"))) -> 0.57142857
A60: =Masters!A11 -> DEL-KNP | B60: =Masters!B11&" - "&Masters!C11 -> Delhi - Kanpur | C60: =COUNTIFS('Shipment Data'!$D$2:$D$1000,$A60,'Shipment Data'!$Q$2:$Q$1000,"OK") -> 20 | D60: =SUMIFS('Shipment Data'!$I$2:$I$1000,'Shipment Data'!$D$2:$D$1000,$A60,'Shipment Data'!$Q$2:$Q$1000,"OK") -> 432045 | E60: =IF(COUNTIFS('Shipment Data'!$D$2:$D$1000,$A60,'Shipment Data'!$Q$2:$Q$1000,"OK",'Shipment Data'!$O$2:$O$1000,"Yes")+COUNTIFS('Shipment Data'!$D$2:$D$1000,$A60,'Shipment Data'!$Q$2:$Q$1000,"OK",'Shipment Data'!$O$2:$O$1000,"No")=0,0,COUNTIFS('Shipment Data'!$D$2:$D$1000,$A60,'Shipment Data'!$Q$2:$Q$1000,"OK",'Shipment Data'!$O$2:$O$1000,"Yes")/(COUNTIFS('Shipment Data'!$D$2:$D$1000,$A60,'Shipment Data'!$Q$2:$Q$1000,"OK",'Shipment Data'!$O$2:$O$1000,"Yes")+COUNTIFS('Shipment Data'!$D$2:$D$1000,$A60,'Shipment Data'!$Q$2:$Q$1000,"OK",'Shipment Data'!$O$2:$O$1000,"No"))) -> 0.8
A61: =Masters!A12 -> DEL-AGR | B61: =Masters!B12&" - "&Masters!C12 -> Delhi - Agra | C61: =COUNTIFS('Shipment Data'!$D$2:$D$1000,$A61,'Shipment Data'!$Q$2:$Q$1000,"OK") -> 18 | D61: =SUMIFS('Shipment Data'!$I$2:$I$1000,'Shipment Data'!$D$2:$D$1000,$A61,'Shipment Data'!$Q$2:$Q$1000,"OK") -> 285628 | E61: =IF(COUNTIFS('Shipment Data'!$D$2:$D$1000,$A61,'Shipment Data'!$Q$2:$Q$1000,"OK",'Shipment Data'!$O$2:$O$1000,"Yes")+COUNTIFS('Shipment Data'!$D$2:$D$1000,$A61,'Shipment Data'!$Q$2:$Q$1000,"OK",'Shipment Data'!$O$2:$O$1000,"No")=0,0,COUNTIFS('Shipment Data'!$D$2:$D$1000,$A61,'Shipment Data'!$Q$2:$Q$1000,"OK",'Shipment Data'!$O$2:$O$1000,"Yes")/(COUNTIFS('Shipment Data'!$D$2:$D$1000,$A61,'Shipment Data'!$Q$2:$Q$1000,"OK",'Shipment Data'!$O$2:$O$1000,"Yes")+COUNTIFS('Shipment Data'!$D$2:$D$1000,$A61,'Shipment Data'!$Q$2:$Q$1000,"OK",'Shipment Data'!$O$2:$O$1000,"No"))) -> 0.72222222
A62: =Masters!A13 -> GZB-MRT | B62: =Masters!B13&" - "&Masters!C13 -> Ghaziabad - Meerut | C62: =COUNTIFS('Shipment Data'!$D$2:$D$1000,$A62,'Shipment Data'!$Q$2:$Q$1000,"OK") -> 33 | D62: =SUMIFS('Shipment Data'!$I$2:$I$1000,'Shipment Data'!$D$2:$D$1000,$A62,'Shipment Data'!$Q$2:$Q$1000,"OK") -> 350802 | E62: =IF(COUNTIFS('Shipment Data'!$D$2:$D$1000,$A62,'Shipment Data'!$Q$2:$Q$1000,"OK",'Shipment Data'!$O$2:$O$1000,"Yes")+COUNTIFS('Shipment Data'!$D$2:$D$1000,$A62,'Shipment Data'!$Q$2:$Q$1000,"OK",'Shipment Data'!$O$2:$O$1000,"No")=0,0,COUNTIFS('Shipment Data'!$D$2:$D$1000,$A62,'Shipment Data'!$Q$2:$Q$1000,"OK",'Shipment Data'!$O$2:$O$1000,"Yes")/(COUNTIFS('Shipment Data'!$D$2:$D$1000,$A62,'Shipment Data'!$Q$2:$Q$1000,"OK",'Shipment Data'!$O$2:$O$1000,"Yes")+COUNTIFS('Shipment Data'!$D$2:$D$1000,$A62,'Shipment Data'!$Q$2:$Q$1000,"OK",'Shipment Data'!$O$2:$O$1000,"No"))) -> 0.59375
A63: =Masters!A14 -> DEL-DED | B63: =Masters!B14&" - "&Masters!C14 -> Delhi - Dehradun | C63: =COUNTIFS('Shipment Data'!$D$2:$D$1000,$A63,'Shipment Data'!$Q$2:$Q$1000,"OK") -> 16 | D63: =SUMIFS('Shipment Data'!$I$2:$I$1000,'Shipment Data'!$D$2:$D$1000,$A63,'Shipment Data'!$Q$2:$Q$1000,"OK") -> 275680 | E63: =IF(COUNTIFS('Shipment Data'!$D$2:$D$1000,$A63,'Shipment Data'!$Q$2:$Q$1000,"OK",'Shipment Data'!$O$2:$O$1000,"Yes")+COUNTIFS('Shipment Data'!$D$2:$D$1000,$A63,'Shipment Data'!$Q$2:$Q$1000,"OK",'Shipment Data'!$O$2:$O$1000,"No")=0,0,COUNTIFS('Shipment Data'!$D$2:$D$1000,$A63,'Shipment Data'!$Q$2:$Q$1000,"OK",'Shipment Data'!$O$2:$O$1000,"Yes")/(COUNTIFS('Shipment Data'!$D$2:$D$1000,$A63,'Shipment Data'!$Q$2:$Q$1000,"OK",'Shipment Data'!$O$2:$O$1000,"Yes")+COUNTIFS('Shipment Data'!$D$2:$D$1000,$A63,'Shipment Data'!$Q$2:$Q$1000,"OK",'Shipment Data'!$O$2:$O$1000,"No"))) -> 0.625
A64: =Masters!A15 -> DEL-BPL | B64: =Masters!B15&" - "&Masters!C15 -> Delhi - Bhopal | C64: =COUNTIFS('Shipment Data'!$D$2:$D$1000,$A64,'Shipment Data'!$Q$2:$Q$1000,"OK") -> 23 | D64: =SUMIFS('Shipment Data'!$I$2:$I$1000,'Shipment Data'!$D$2:$D$1000,$A64,'Shipment Data'!$Q$2:$Q$1000,"OK") -> 873360 | E64: =IF(COUNTIFS('Shipment Data'!$D$2:$D$1000,$A64,'Shipment Data'!$Q$2:$Q$1000,"OK",'Shipment Data'!$O$2:$O$1000,"Yes")+COUNTIFS('Shipment Data'!$D$2:$D$1000,$A64,'Shipment Data'!$Q$2:$Q$1000,"OK",'Shipment Data'!$O$2:$O$1000,"No")=0,0,COUNTIFS('Shipment Data'!$D$2:$D$1000,$A64,'Shipment Data'!$Q$2:$Q$1000,"OK",'Shipment Data'!$O$2:$O$1000,"Yes")/(COUNTIFS('Shipment Data'!$D$2:$D$1000,$A64,'Shipment Data'!$Q$2:$Q$1000,"OK",'Shipment Data'!$O$2:$O$1000,"Yes")+COUNTIFS('Shipment Data'!$D$2:$D$1000,$A64,'Shipment Data'!$Q$2:$Q$1000,"OK",'Shipment Data'!$O$2:$O$1000,"No"))) -> 0.65217391
A65: =Masters!A16 -> DEL-IDR | B65: =Masters!B16&" - "&Masters!C16 -> Delhi - Indore | C65: =COUNTIFS('Shipment Data'!$D$2:$D$1000,$A65,'Shipment Data'!$Q$2:$Q$1000,"OK") -> 13 | D65: =SUMIFS('Shipment Data'!$I$2:$I$1000,'Shipment Data'!$D$2:$D$1000,$A65,'Shipment Data'!$Q$2:$Q$1000,"OK") -> 466380 | E65: =IF(COUNTIFS('Shipment Data'!$D$2:$D$1000,$A65,'Shipment Data'!$Q$2:$Q$1000,"OK",'Shipment Data'!$O$2:$O$1000,"Yes")+COUNTIFS('Shipment Data'!$D$2:$D$1000,$A65,'Shipment Data'!$Q$2:$Q$1000,"OK",'Shipment Data'!$O$2:$O$1000,"No")=0,0,COUNTIFS('Shipment Data'!$D$2:$D$1000,$A65,'Shipment Data'!$Q$2:$Q$1000,"OK",'Shipment Data'!$O$2:$O$1000,"Yes")/(COUNTIFS('Shipment Data'!$D$2:$D$1000,$A65,'Shipment Data'!$Q$2:$Q$1000,"OK",'Shipment Data'!$O$2:$O$1000,"Yes")+COUNTIFS('Shipment Data'!$D$2:$D$1000,$A65,'Shipment Data'!$Q$2:$Q$1000,"OK",'Shipment Data'!$O$2:$O$1000,"No"))) -> 0.58333333
A66: Total | C66: =SUM(C54:C65) -> 279 | D66: =SUM(D54:D65) -> 7992228 | E66: =C5 -> 0.65441176

Sheet MIS Report
A1: MIS Report - Shipments (Daily / Weekly / Monthly)
A2: Pick a Report Type and a date in the yellow cells. Everything below updates. Only records with Data Check = OK are counted.
A3: Report Type | B3: Monthly
A4: Report Date | B4: 46249
A5: Period Start | B5: =IF(B3="Daily",B4,IF(B3="Weekly",B4-WEEKDAY(B4,2)+1,DATE(YEAR(B4),MONTH(B4),1))) -> 46235
A6: Period End | B6: =IF(B3="Daily",B4,IF(B3="Weekly",B5+6,DATE(YEAR(B4),MONTH(B4)+1,0))) -> 46265
A8: Key Metrics | B8: Value
A9: Total Shipments | B9: =COUNTIFS('Shipment Data'!$B$2:$B$1000,">="&$B$5,'Shipment Data'!$B$2:$B$1000,"<="&$B$6,'Shipment Data'!$Q$2:$Q$1000,"OK") -> 64
A10: Total Weight (kg) | B10: =SUMIFS('Shipment Data'!$G$2:$G$1000,'Shipment Data'!$B$2:$B$1000,">="&$B$5,'Shipment Data'!$B$2:$B$1000,"<="&$B$6,'Shipment Data'!$Q$2:$Q$1000,"OK") -> 309210
A11: Total Freight Revenue (Rs) | B11: =SUMIFS('Shipment Data'!$I$2:$I$1000,'Shipment Data'!$B$2:$B$1000,">="&$B$5,'Shipment Data'!$B$2:$B$1000,"<="&$B$6,'Shipment Data'!$Q$2:$Q$1000,"OK") -> 1561381
A12: Avg Freight per Shipment (Rs) | B12: =IF(B9=0,0,B11/B9) -> 24396.578
A13: Delivered | B13: =COUNTIFS('Shipment Data'!$B$2:$B$1000,">="&$B$5,'Shipment Data'!$B$2:$B$1000,"<="&$B$6,'Shipment Data'!$Q$2:$Q$1000,"OK",'Shipment Data'!$M$2:$M$1000,"Delivered") -> 64
A14: In Transit | B14: =COUNTIFS('Shipment Data'!$B$2:$B$1000,">="&$B$5,'Shipment Data'!$B$2:$B$1000,"<="&$B$6,'Shipment Data'!$Q$2:$Q$1000,"OK",'Shipment Data'!$M$2:$M$1000,"In Transit") -> 0
A15: On-Time Deliveries | B15: =COUNTIFS('Shipment Data'!$B$2:$B$1000,">="&$B$5,'Shipment Data'!$B$2:$B$1000,"<="&$B$6,'Shipment Data'!$Q$2:$Q$1000,"OK",'Shipment Data'!$O$2:$O$1000,"Yes") -> 41
A16: Late Deliveries | B16: =COUNTIFS('Shipment Data'!$B$2:$B$1000,">="&$B$5,'Shipment Data'!$B$2:$B$1000,"<="&$B$6,'Shipment Data'!$Q$2:$Q$1000,"OK",'Shipment Data'!$O$2:$O$1000,"No") -> 23
A17: On-Time Delivery % | B17: =IF(B15+B16=0,"n/a",B15/(B15+B16)) -> 0.640625
A18: Avg Delay of Late Deliveries (days) | B18: =IFERROR(AVERAGEIFS('Shipment Data'!$N$2:$N$1000,'Shipment Data'!$B$2:$B$1000,">="&$B$5,'Shipment Data'!$B$2:$B$1000,"<="&$B$6,'Shipment Data'!$Q$2:$Q$1000,"OK",'Shipment Data'!$O$2:$O$1000,"No"),0) -> 1.6956522
A19: Records Excluded (data errors in period) | B19: =COUNTIFS('Shipment Data'!$B$2:$B$1000,">="&$B$5,'Shipment Data'!$B$2:$B$1000,"<="&$B$6,'Shipment Data'!$Q$2:$Q$1000,"<>OK") -> 6
A22: Client | B22: Shipments | C22: Weight (kg) | D22: Freight (Rs) | E22: On-Time % | F22: Late Deliveries
A23: =Masters!G5 -> Shree Ganesh Traders | B23: =COUNTIFS('Shipment Data'!$B$2:$B$1000,">="&$B$5,'Shipment Data'!$B$2:$B$1000,"<="&$B$6,'Shipment Data'!$Q$2:$Q$1000,"OK",'Shipment Data'!$C$2:$C$1000,$A23) -> 11 | C23: =SUMIFS('Shipment Data'!$G$2:$G$1000,'Shipment Data'!$B$2:$B$1000,">="&$B$5,'Shipment Data'!$B$2:$B$1000,"<="&$B$6,'Shipment Data'!$Q$2:$Q$1000,"OK",'Shipment Data'!$C$2:$C$1000,$A23) -> 60800 | D23: =SUMIFS('Shipment Data'!$I$2:$I$1000,'Shipment Data'!$B$2:$B$1000,">="&$B$5,'Shipment Data'!$B$2:$B$1000,"<="&$B$6,'Shipment Data'!$Q$2:$Q$1000,"OK",'Shipment Data'!$C$2:$C$1000,$A23) -> 341832 | E23: =IF(COUNTIFS('Shipment Data'!$B$2:$B$1000,">="&$B$5,'Shipment Data'!$B$2:$B$1000,"<="&$B$6,'Shipment Data'!$Q$2:$Q$1000,"OK",'Shipment Data'!$C$2:$C$1000,$A23,'Shipment Data'!$O$2:$O$1000,"Yes")+F23=0,"n/a",COUNTIFS('Shipment Data'!$B$2:$B$1000,">="&$B$5,'Shipment Data'!$B$2:$B$1000,"<="&$B$6,'Shipment Data'!$Q$2:$Q$1000,"OK",'Shipment Data'!$C$2:$C$1000,$A23,'Shipment Data'!$O$2:$O$1000,"Yes")/(COUNTIFS('Shipment Data'!$B$2:$B$1000,">="&$B$5,'Shipment Data'!$B$2:$B$1000,"<="&$B$6,'Shipment Data'!$Q$2:$Q$1000,"OK",'Shipment Data'!$C$2:$C$1000,$A23,'Shipment Data'!$O$2:$O$1000,"Yes")+F23)) -> 0.63636364 | F23: =COUNTIFS('Shipment Data'!$B$2:$B$1000,">="&$B$5,'Shipment Data'!$B$2:$B$1000,"<="&$B$6,'Shipment Data'!$Q$2:$Q$1000,"OK",'Shipment Data'!$C$2:$C$1000,$A23,'Shipment Data'!$O$2:$O$1000,"No") -> 4
A24: =Masters!G6 -> Metro Fabrics Pvt Ltd | B24: =COUNTIFS('Shipment Data'!$B$2:$B$1000,">="&$B$5,'Shipment Data'!$B$2:$B$1000,"<="&$B$6,'Shipment Data'!$Q$2:$Q$1000,"OK",'Shipment Data'!$C$2:$C$1000,$A24) -> 6 | C24: =SUMIFS('Shipment Data'!$G$2:$G$1000,'Shipment Data'!$B$2:$B$1000,">="&$B$5,'Shipment Data'!$B$2:$B$1000,"<="&$B$6,'Shipment Data'!$Q$2:$Q$1000,"OK",'Shipment Data'!$C$2:$C$1000,$A24) -> 21190 | D24: =SUMIFS('Shipment Data'!$I$2:$I$1000,'Shipment Data'!$B$2:$B$1000,">="&$B$5,'Shipment Data'!$B$2:$B$1000,"<="&$B$6,'Shipment Data'!$Q$2:$Q$1000,"OK",'Shipment Data'!$C$2:$C$1000,$A24) -> 93204 | E24: =IF(COUNTIFS('Shipment Data'!$B$2:$B$1000,">="&$B$5,'Shipment Data'!$B$2:$B$1000,"<="&$B$6,'Shipment Data'!$Q$2:$Q$1000,"OK",'Shipment Data'!$C$2:$C$1000,$A24,'Shipment Data'!$O$2:$O$1000,"Yes")+F24=0,"n/a",COUNTIFS('Shipment Data'!$B$2:$B$1000,">="&$B$5,'Shipment Data'!$B$2:$B$1000,"<="&$B$6,'Shipment Data'!$Q$2:$Q$1000,"OK",'Shipment Data'!$C$2:$C$1000,$A24,'Shipment Data'!$O$2:$O$1000,"Yes")/(COUNTIFS('Shipment Data'!$B$2:$B$1000,">="&$B$5,'Shipment Data'!$B$2:$B$1000,"<="&$B$6,'Shipment Data'!$Q$2:$Q$1000,"OK",'Shipment Data'!$C$2:$C$1000,$A24,'Shipment Data'!$O$2:$O$1000,"Yes")+F24)) -> 0.66666667 | F24: =COUNTIFS('Shipment Data'!$B$2:$B$1000,">="&$B$5,'Shipment Data'!$B$2:$B$1000,"<="&$B$6,'Shipment Data'!$Q$2:$Q$1000,"OK",'Shipment Data'!$C$2:$C$1000,$A24,'Shipment Data'!$O$2:$O$1000,"No") -> 2
A25: =Masters!G7 -> Apex Electronics | B25: =COUNTIFS('Shipment Data'!$B$2:$B$1000,">="&$B$5,'Shipment Data'!$B$2:$B$1000,"<="&$B$6,'Shipment Data'!$Q$2:$Q$1000,"OK",'Shipment Data'!$C$2:$C$1000,$A25) -> 12 | C25: =SUMIFS('Shipment Data'!$G$2:$G$1000,'Shipment Data'!$B$2:$B$1000,">="&$B$5,'Shipment Data'!$B$2:$B$1000,"<="&$B$6,'Shipment Data'!$Q$2:$Q$1000,"OK",'Shipment Data'!$C$2:$C$1000,$A25) -> 61430 | D25: =SUMIFS('Shipment Data'!$I$2:$I$1000,'Shipment Data'!$B$2:$B$1000,">="&$B$5,'Shipment Data'!$B$2:$B$1000,"<="&$B$6,'Shipment Data'!$Q$2:$Q$1000,"OK",'Shipment Data'!$C$2:$C$1000,$A25) -> 286056 | E25: =IF(COUNTIFS('Shipment Data'!$B$2:$B$1000,">="&$B$5,'Shipment Data'!$B$2:$B$1000,"<="&$B$6,'Shipment Data'!$Q$2:$Q$1000,"OK",'Shipment Data'!$C$2:$C$1000,$A25,'Shipment Data'!$O$2:$O$1000,"Yes")+F25=0,"n/a",COUNTIFS('Shipment Data'!$B$2:$B$1000,">="&$B$5,'Shipment Data'!$B$2:$B$1000,"<="&$B$6,'Shipment Data'!$Q$2:$Q$1000,"OK",'Shipment Data'!$C$2:$C$1000,$A25,'Shipment Data'!$O$2:$O$1000,"Yes")/(COUNTIFS('Shipment Data'!$B$2:$B$1000,">="&$B$5,'Shipment Data'!$B$2:$B$1000,"<="&$B$6,'Shipment Data'!$Q$2:$Q$1000,"OK",'Shipment Data'!$C$2:$C$1000,$A25,'Shipment Data'!$O$2:$O$1000,"Yes")+F25)) -> 0.58333333 | F25: =COUNTIFS('Shipment Data'!$B$2:$B$1000,">="&$B$5,'Shipment Data'!$B$2:$B$1000,"<="&$B$6,'Shipment Data'!$Q$2:$Q$1000,"OK",'Shipment Data'!$C$2:$C$1000,$A25,'Shipment Data'!$O$2:$O$1000,"No") -> 5
A26: =Masters!G8 -> Sharma Agro Foods | B26: =COUNTIFS('Shipment Data'!$B$2:$B$1000,">="&$B$5,'Shipment Data'!$B$2:$B$1000,"<="&$B$6,'Shipment Data'!$Q$2:$Q$1000,"OK",'Shipment Data'!$C$2:$C$1000,$A26) -> 12 | C26: =SUMIFS('Shipment Data'!$G$2:$G$1000,'Shipment Data'!$B$2:$B$1000,">="&$B$5,'Shipment Data'!$B$2:$B$1000,"<="&$B$6,'Shipment Data'!$Q$2:$Q$1000,"OK",'Shipment Data'!$C$2:$C$1000,$A26) -> 50990 | D26: =SUMIFS('Shipment Data'!$I$2:$I$1000,'Shipment Data'!$B$2:$B$1000,">="&$B$5,'Shipment Data'!$B$2:$B$1000,"<="&$B$6,'Shipment Data'!$Q$2:$Q$1000,"OK",'Shipment Data'!$C$2:$C$1000,$A26) -> 247709 | E26: =IF(COUNTIFS('Shipment Data'!$B$2:$B$1000,">="&$B$5,'Shipment Data'!$B$2:$B$1000,"<="&$B$6,'Shipment Data'!$Q$2:$Q$1000,"OK",'Shipment Data'!$C$2:$C$1000,$A26,'Shipment Data'!$O$2:$O$1000,"Yes")+F26=0,"n/a",COUNTIFS('Shipment Data'!$B$2:$B$1000,">="&$B$5,'Shipment Data'!$B$2:$B$1000,"<="&$B$6,'Shipment Data'!$Q$2:$Q$1000,"OK",'Shipment Data'!$C$2:$C$1000,$A26,'Shipment Data'!$O$2:$O$1000,"Yes")/(COUNTIFS('Shipment Data'!$B$2:$B$1000,">="&$B$5,'Shipment Data'!$B$2:$B$1000,"<="&$B$6,'Shipment Data'!$Q$2:$Q$1000,"OK",'Shipment Data'!$C$2:$C$1000,$A26,'Shipment Data'!$O$2:$O$1000,"Yes")+F26)) -> 0.5 | F26: =COUNTIFS('Shipment Data'!$B$2:$B$1000,">="&$B$5,'Shipment Data'!$B$2:$B$1000,"<="&$B$6,'Shipment Data'!$Q$2:$Q$1000,"OK",'Shipment Data'!$C$2:$C$1000,$A26,'Shipment Data'!$O$2:$O$1000,"No") -> 6
A27: =Masters!G9 -> Bharat Auto Components | B27: =COUNTIFS('Shipment Data'!$B$2:$B$1000,">="&$B$5,'Shipment Data'!$B$2:$B$1000,"<="&$B$6,'Shipment Data'!$Q$2:$Q$1000,"OK",'Shipment Data'!$C$2:$C$1000,$A27) -> 9 | C27: =SUMIFS('Shipment Data'!$G$2:$G$1000,'Shipment Data'!$B$2:$B$1000,">="&$B$5,'Shipment Data'!$B$2:$B$1000,"<="&$B$6,'Shipment Data'!$Q$2:$Q$1000,"OK",'Shipment Data'!$C$2:$C$1000,$A27) -> 40430 | D27: =SUMIFS('Shipment Data'!$I$2:$I$1000,'Shipment Data'!$B$2:$B$1000,">="&$B$5,'Shipment Data'!$B$2:$B$1000,"<="&$B$6,'Shipment Data'!$Q$2:$Q$1000,"OK",'Shipment Data'!$C$2:$C$1000,$A27) -> 209757 | E27: =IF(COUNTIFS('Shipment Data'!$B$2:$B$1000,">="&$B$5,'Shipment Data'!$B$2:$B$1000,"<="&$B$6,'Shipment Data'!$Q$2:$Q$1000,"OK",'Shipment Data'!$C$2:$C$1000,$A27,'Shipment Data'!$O$2:$O$1000,"Yes")+F27=0,"n/a",COUNTIFS('Shipment Data'!$B$2:$B$1000,">="&$B$5,'Shipment Data'!$B$2:$B$1000,"<="&$B$6,'Shipment Data'!$Q$2:$Q$1000,"OK",'Shipment Data'!$C$2:$C$1000,$A27,'Shipment Data'!$O$2:$O$1000,"Yes")/(COUNTIFS('Shipment Data'!$B$2:$B$1000,">="&$B$5,'Shipment Data'!$B$2:$B$1000,"<="&$B$6,'Shipment Data'!$Q$2:$Q$1000,"OK",'Shipment Data'!$C$2:$C$1000,$A27,'Shipment Data'!$O$2:$O$1000,"Yes")+F27)) -> 0.66666667 | F27: =COUNTIFS('Shipment Data'!$B$2:$B$1000,">="&$B$5,'Shipment Data'!$B$2:$B$1000,"<="&$B$6,'Shipment Data'!$Q$2:$Q$1000,"OK",'Shipment Data'!$C$2:$C$1000,$A27,'Shipment Data'!$O$2:$O$1000,"No") -> 3
A28: =Masters!G10 -> Kailash Pharma | B28: =COUNTIFS('Shipment Data'!$B$2:$B$1000,">="&$B$5,'Shipment Data'!$B$2:$B$1000,"<="&$B$6,'Shipment Data'!$Q$2:$Q$1000,"OK",'Shipment Data'!$C$2:$C$1000,$A28) -> 4 | C28: =SUMIFS('Shipment Data'!$G$2:$G$1000,'Shipment Data'!$B$2:$B$1000,">="&$B$5,'Shipment Data'!$B$2:$B$1000,"<="&$B$6,'Shipment Data'!$Q$2:$Q$1000,"OK",'Shipment Data'!$C$2:$C$1000,$A28) -> 16700 | D28: =SUMIFS('Shipment Data'!$I$2:$I$1000,'Shipment Data'!$B$2:$B$1000,">="&$B$5,'Shipment Data'!$B$2:$B$1000,"<="&$B$6,'Shipment Data'!$Q$2:$Q$1000,"OK",'Shipment Data'!$C$2:$C$1000,$A28) -> 67310 | E28: =IF(COUNTIFS('Shipment Data'!$B$2:$B$1000,">="&$B$5,'Shipment Data'!$B$2:$B$1000,"<="&$B$6,'Shipment Data'!$Q$2:$Q$1000,"OK",'Shipment Data'!$C$2:$C$1000,$A28,'Shipment Data'!$O$2:$O$1000,"Yes")+F28=0,"n/a",COUNTIFS('Shipment Data'!$B$2:$B$1000,">="&$B$5,'Shipment Data'!$B$2:$B$1000,"<="&$B$6,'Shipment Data'!$Q$2:$Q$1000,"OK",'Shipment Data'!$C$2:$C$1000,$A28,'Shipment Data'!$O$2:$O$1000,"Yes")/(COUNTIFS('Shipment Data'!$B$2:$B$1000,">="&$B$5,'Shipment Data'!$B$2:$B$1000,"<="&$B$6,'Shipment Data'!$Q$2:$Q$1000,"OK",'Shipment Data'!$C$2:$C$1000,$A28,'Shipment Data'!$O$2:$O$1000,"Yes")+F28)) -> 0.75 | F28: =COUNTIFS('Shipment Data'!$B$2:$B$1000,">="&$B$5,'Shipment Data'!$B$2:$B$1000,"<="&$B$6,'Shipment Data'!$Q$2:$Q$1000,"OK",'Shipment Data'!$C$2:$C$1000,$A28,'Shipment Data'!$O$2:$O$1000,"No") -> 1
A29: =Masters!G11 -> Sunrise Furniture | B29: =COUNTIFS('Shipment Data'!$B$2:$B$1000,">="&$B$5,'Shipment Data'!$B$2:$B$1000,"<="&$B$6,'Shipment Data'!$Q$2:$Q$1000,"OK",'Shipment Data'!$C$2:$C$1000,$A29) -> 4 | C29: =SUMIFS('Shipment Data'!$G$2:$G$1000,'Shipment Data'!$B$2:$B$1000,">="&$B$5,'Shipment Data'!$B$2:$B$1000,"<="&$B$6,'Shipment Data'!$Q$2:$Q$1000,"OK",'Shipment Data'!$C$2:$C$1000,$A29) -> 25130 | D29: =SUMIFS('Shipment Data'!$I$2:$I$1000,'Shipment Data'!$B$2:$B$1000,">="&$B$5,'Shipment Data'!$B$2:$B$1000,"<="&$B$6,'Shipment Data'!$Q$2:$Q$1000,"OK",'Shipment Data'!$C$2:$C$1000,$A29) -> 111173 | E29: =IF(COUNTIFS('Shipment Data'!$B$2:$B$1000,">="&$B$5,'Shipment Data'!$B$2:$B$1000,"<="&$B$6,'Shipment Data'!$Q$2:$Q$1000,"OK",'Shipment Data'!$C$2:$C$1000,$A29,'Shipment Data'!$O$2:$O$1000,"Yes")+F29=0,"n/a",COUNTIFS('Shipment Data'!$B$2:$B$1000,">="&$B$5,'Shipment Data'!$B$2:$B$1000,"<="&$B$6,'Shipment Data'!$Q$2:$Q$1000,"OK",'Shipment Data'!$C$2:$C$1000,$A29,'Shipment Data'!$O$2:$O$1000,"Yes")/(COUNTIFS('Shipment Data'!$B$2:$B$1000,">="&$B$5,'Shipment Data'!$B$2:$B$1000,"<="&$B$6,'Shipment Data'!$Q$2:$Q$1000,"OK",'Shipment Data'!$C$2:$C$1000,$A29,'Shipment Data'!$O$2:$O$1000,"Yes")+F29)) -> 1 | F29: =COUNTIFS('Shipment Data'!$B$2:$B$1000,">="&$B$5,'Shipment Data'!$B$2:$B$1000,"<="&$B$6,'Shipment Data'!$Q$2:$Q$1000,"OK",'Shipment Data'!$C$2:$C$1000,$A29,'Shipment Data'!$O$2:$O$1000,"No") -> 0
A30: =Masters!G12 -> Delta Packaging | B30: =COUNTIFS('Shipment Data'!$B$2:$B$1000,">="&$B$5,'Shipment Data'!$B$2:$B$1000,"<="&$B$6,'Shipment Data'!$Q$2:$Q$1000,"OK",'Shipment Data'!$C$2:$C$1000,$A30) -> 2 | C30: =SUMIFS('Shipment Data'!$G$2:$G$1000,'Shipment Data'!$B$2:$B$1000,">="&$B$5,'Shipment Data'!$B$2:$B$1000,"<="&$B$6,'Shipment Data'!$Q$2:$Q$1000,"OK",'Shipment Data'!$C$2:$C$1000,$A30) -> 8900 | D30: =SUMIFS('Shipment Data'!$I$2:$I$1000,'Shipment Data'!$B$2:$B$1000,">="&$B$5,'Shipment Data'!$B$2:$B$1000,"<="&$B$6,'Shipment Data'!$Q$2:$Q$1000,"OK",'Shipment Data'!$C$2:$C$1000,$A30) -> 56920 | E30: =IF(COUNTIFS('Shipment Data'!$B$2:$B$1000,">="&$B$5,'Shipment Data'!$B$2:$B$1000,"<="&$B$6,'Shipment Data'!$Q$2:$Q$1000,"OK",'Shipment Data'!$C$2:$C$1000,$A30,'Shipment Data'!$O$2:$O$1000,"Yes")+F30=0,"n/a",COUNTIFS('Shipment Data'!$B$2:$B$1000,">="&$B$5,'Shipment Data'!$B$2:$B$1000,"<="&$B$6,'Shipment Data'!$Q$2:$Q$1000,"OK",'Shipment Data'!$C$2:$C$1000,$A30,'Shipment Data'!$O$2:$O$1000,"Yes")/(COUNTIFS('Shipment Data'!$B$2:$B$1000,">="&$B$5,'Shipment Data'!$B$2:$B$1000,"<="&$B$6,'Shipment Data'!$Q$2:$Q$1000,"OK",'Shipment Data'!$C$2:$C$1000,$A30,'Shipment Data'!$O$2:$O$1000,"Yes")+F30)) -> 0 | F30: =COUNTIFS('Shipment Data'!$B$2:$B$1000,">="&$B$5,'Shipment Data'!$B$2:$B$1000,"<="&$B$6,'Shipment Data'!$Q$2:$Q$1000,"OK",'Shipment Data'!$C$2:$C$1000,$A30,'Shipment Data'!$O$2:$O$1000,"No") -> 2
A31: =Masters!G13 -> Nova Home Appliances | B31: =COUNTIFS('Shipment Data'!$B$2:$B$1000,">="&$B$5,'Shipment Data'!$B$2:$B$1000,"<="&$B$6,'Shipment Data'!$Q$2:$Q$1000,"OK",'Shipment Data'!$C$2:$C$1000,$A31) -> 4 | C31: =SUMIFS('Shipment Data'!$G$2:$G$1000,'Shipment Data'!$B$2:$B$1000,">="&$B$5,'Shipment Data'!$B$2:$B$1000,"<="&$B$6,'Shipment Data'!$Q$2:$Q$1000,"OK",'Shipment Data'!$C$2:$C$1000,$A31) -> 23640 | D31: =SUMIFS('Shipment Data'!$I$2:$I$1000,'Shipment Data'!$B$2:$B$1000,">="&$B$5,'Shipment Data'!$B$2:$B$1000,"<="&$B$6,'Shipment Data'!$Q$2:$Q$1000,"OK",'Shipment Data'!$C$2:$C$1000,$A31) -> 147420 | E31: =IF(COUNTIFS('Shipment Data'!$B$2:$B$1000,">="&$B$5,'Shipment Data'!$B$2:$B$1000,"<="&$B$6,'Shipment Data'!$Q$2:$Q$1000,"OK",'Shipment Data'!$C$2:$C$1000,$A31,'Shipment Data'!$O$2:$O$1000,"Yes")+F31=0,"n/a",COUNTIFS('Shipment Data'!$B$2:$B$1000,">="&$B$5,'Shipment Data'!$B$2:$B$1000,"<="&$B$6,'Shipment Data'!$Q$2:$Q$1000,"OK",'Shipment Data'!$C$2:$C$1000,$A31,'Shipment Data'!$O$2:$O$1000,"Yes")/(COUNTIFS('Shipment Data'!$B$2:$B$1000,">="&$B$5,'Shipment Data'!$B$2:$B$1000,"<="&$B$6,'Shipment Data'!$Q$2:$Q$1000,"OK",'Shipment Data'!$C$2:$C$1000,$A31,'Shipment Data'!$O$2:$O$1000,"Yes")+F31)) -> 1 | F31: =COUNTIFS('Shipment Data'!$B$2:$B$1000,">="&$B$5,'Shipment Data'!$B$2:$B$1000,"<="&$B$6,'Shipment Data'!$Q$2:$Q$1000,"OK",'Shipment Data'!$C$2:$C$1000,$A31,'Shipment Data'!$O$2:$O$1000,"No") -> 0
A32: =Masters!G14 -> Krishna Steel Works | B32: =COUNTIFS('Shipment Data'!$B$2:$B$1000,">="&$B$5,'Shipment Data'!$B$2:$B$1000,"<="&$B$6,'Shipment Data'!$Q$2:$Q$1000,"OK",'Shipment Data'!$C$2:$C$1000,$A32) -> 0 | C32: =SUMIFS('Shipment Data'!$G$2:$G$1000,'Shipment Data'!$B$2:$B$1000,">="&$B$5,'Shipment Data'!$B$2:$B$1000,"<="&$B$6,'Shipment Data'!$Q$2:$Q$1000,"OK",'Shipment Data'!$C$2:$C$1000,$A32) -> 0 | D32: =SUMIFS('Shipment Data'!$I$2:$I$1000,'Shipment Data'!$B$2:$B$1000,">="&$B$5,'Shipment Data'!$B$2:$B$1000,"<="&$B$6,'Shipment Data'!$Q$2:$Q$1000,"OK",'Shipment Data'!$C$2:$C$1000,$A32) -> 0 | E32: =IF(COUNTIFS('Shipment Data'!$B$2:$B$1000,">="&$B$5,'Shipment Data'!$B$2:$B$1000,"<="&$B$6,'Shipment Data'!$Q$2:$Q$1000,"OK",'Shipment Data'!$C$2:$C$1000,$A32,'Shipment Data'!$O$2:$O$1000,"Yes")+F32=0,"n/a",COUNTIFS('Shipment Data'!$B$2:$B$1000,">="&$B$5,'Shipment Data'!$B$2:$B$1000,"<="&$B$6,'Shipment Data'!$Q$2:$Q$1000,"OK",'Shipment Data'!$C$2:$C$1000,$A32,'Shipment Data'!$O$2:$O$1000,"Yes")/(COUNTIFS('Shipment Data'!$B$2:$B$1000,">="&$B$5,'Shipment Data'!$B$2:$B$1000,"<="&$B$6,'Shipment Data'!$Q$2:$Q$1000,"OK",'Shipment Data'!$C$2:$C$1000,$A32,'Shipment Data'!$O$2:$O$1000,"Yes")+F32)) -> n/a | F32: =COUNTIFS('Shipment Data'!$B$2:$B$1000,">="&$B$5,'Shipment Data'!$B$2:$B$1000,"<="&$B$6,'Shipment Data'!$Q$2:$Q$1000,"OK",'Shipment Data'!$C$2:$C$1000,$A32,'Shipment Data'!$O$2:$O$1000,"No") -> 0
A33: Total | B33: =SUM(B23:B32) -> 64 | C33: =SUM(C23:C32) -> 309210 | D33: =SUM(D23:D32) -> 1561381 | E33: =B17 -> 0.640625 | F33: =SUM(F23:F32) -> 23
A34: Check: client total should equal Total Shipments above (difference below should be 0). | F34: =B33-B9 -> 0
A36: Route Code | B36: Route | C36: Shipments | D36: Freight (Rs) | E36: Late Deliveries
A37: =Masters!A5 -> DEL-JPR | B37: =Masters!B5&" - "&Masters!C5 -> Delhi - Jaipur | C37: =COUNTIFS('Shipment Data'!$B$2:$B$1000,">="&$B$5,'Shipment Data'!$B$2:$B$1000,"<="&$B$6,'Shipment Data'!$Q$2:$Q$1000,"OK",'Shipment Data'!$D$2:$D$1000,$A37) -> 12 | D37: =SUMIFS('Shipment Data'!$I$2:$I$1000,'Shipment Data'!$B$2:$B$1000,">="&$B$5,'Shipment Data'!$B$2:$B$1000,"<="&$B$6,'Shipment Data'!$Q$2:$Q$1000,"OK",'Shipment Data'!$D$2:$D$1000,$A37) -> 250320 | E37: =COUNTIFS('Shipment Data'!$B$2:$B$1000,">="&$B$5,'Shipment Data'!$B$2:$B$1000,"<="&$B$6,'Shipment Data'!$Q$2:$Q$1000,"OK",'Shipment Data'!$D$2:$D$1000,$A37,'Shipment Data'!$O$2:$O$1000,"No") -> 6
A38: =Masters!A6 -> DEL-LKO | B38: =Masters!B6&" - "&Masters!C6 -> Delhi - Lucknow | C38: =COUNTIFS('Shipment Data'!$B$2:$B$1000,">="&$B$5,'Shipment Data'!$B$2:$B$1000,"<="&$B$6,'Shipment Data'!$Q$2:$Q$1000,"OK",'Shipment Data'!$D$2:$D$1000,$A38) -> 7 | D38: =SUMIFS('Shipment Data'!$I$2:$I$1000,'Shipment Data'!$B$2:$B$1000,">="&$B$5,'Shipment Data'!$B$2:$B$1000,"<="&$B$6,'Shipment Data'!$Q$2:$Q$1000,"OK",'Shipment Data'!$D$2:$D$1000,$A38) -> 202904 | E38: =COUNTIFS('Shipment Data'!$B$2:$B$1000,">="&$B$5,'Shipment Data'!$B$2:$B$1000,"<="&$B$6,'Shipment Data'!$Q$2:$Q$1000,"OK",'Shipment Data'!$D$2:$D$1000,$A38,'Shipment Data'!$O$2:$O$1000,"No") -> 2
A39: =Masters!A7 -> DEL-CHD | B39: =Masters!B7&" - "&Masters!C7 -> Delhi - Chandigarh | C39: =COUNTIFS('Shipment Data'!$B$2:$B$1000,">="&$B$5,'Shipment Data'!$B$2:$B$1000,"<="&$B$6,'Shipment Data'!$Q$2:$Q$1000,"OK",'Shipment Data'!$D$2:$D$1000,$A39) -> 10 | D39: =SUMIFS('Shipment Data'!$I$2:$I$1000,'Shipment Data'!$B$2:$B$1000,">="&$B$5,'Shipment Data'!$B$2:$B$1000,"<="&$B$6,'Shipment Data'!$Q$2:$Q$1000,"OK",'Shipment Data'!$D$2:$D$1000,$A39) -> 120750 | E39: =COUNTIFS('Shipment Data'!$B$2:$B$1000,">="&$B$5,'Shipment Data'!$B$2:$B$1000,"<="&$B$6,'Shipment Data'!$Q$2:$Q$1000,"OK",'Shipment Data'!$D$2:$D$1000,$A39,'Shipment Data'!$O$2:$O$1000,"No") -> 1
A40: =Masters!A8 -> DEL-AMD | B40: =Masters!B8&" - "&Masters!C8 -> Delhi - Ahmedabad | C40: =COUNTIFS('Shipment Data'!$B$2:$B$1000,">="&$B$5,'Shipment Data'!$B$2:$B$1000,"<="&$B$6,'Shipment Data'!$Q$2:$Q$1000,"OK",'Shipment Data'!$D$2:$D$1000,$A40) -> 5 | D40: =SUMIFS('Shipment Data'!$I$2:$I$1000,'Shipment Data'!$B$2:$B$1000,">="&$B$5,'Shipment Data'!$B$2:$B$1000,"<="&$B$6,'Shipment Data'!$Q$2:$Q$1000,"OK",'Shipment Data'!$D$2:$D$1000,$A40) -> 133275 | E40: =COUNTIFS('Shipment Data'!$B$2:$B$1000,">="&$B$5,'Shipment Data'!$B$2:$B$1000,"<="&$B$6,'Shipment Data'!$Q$2:$Q$1000,"OK",'Shipment Data'!$D$2:$D$1000,$A40,'Shipment Data'!$O$2:$O$1000,"No") -> 2
A41: =Masters!A9 -> DEL-BOM | B41: =Masters!B9&" - "&Masters!C9 -> Delhi - Mumbai | C41: =COUNTIFS('Shipment Data'!$B$2:$B$1000,">="&$B$5,'Shipment Data'!$B$2:$B$1000,"<="&$B$6,'Shipment Data'!$Q$2:$Q$1000,"OK",'Shipment Data'!$D$2:$D$1000,$A41) -> 3 | D41: =SUMIFS('Shipment Data'!$I$2:$I$1000,'Shipment Data'!$B$2:$B$1000,">="&$B$5,'Shipment Data'!$B$2:$B$1000,"<="&$B$6,'Shipment Data'!$Q$2:$Q$1000,"OK",'Shipment Data'!$D$2:$D$1000,$A41) -> 125495 | E41: =COUNTIFS('Shipment Data'!$B$2:$B$1000,">="&$B$5,'Shipment Data'!$B$2:$B$1000,"<="&$B$6,'Shipment Data'!$Q$2:$Q$1000,"OK",'Shipment Data'!$D$2:$D$1000,$A41,'Shipment Data'!$O$2:$O$1000,"No") -> 2
A42: =Masters!A10 -> DEL-CCU | B42: =Masters!B10&" - "&Masters!C10 -> Delhi - Kolkata | C42: =COUNTIFS('Shipment Data'!$B$2:$B$1000,">="&$B$5,'Shipment Data'!$B$2:$B$1000,"<="&$B$6,'Shipment Data'!$Q$2:$Q$1000,"OK",'Shipment Data'!$D$2:$D$1000,$A42) -> 5 | D42: =SUMIFS('Shipment Data'!$I$2:$I$1000,'Shipment Data'!$B$2:$B$1000,">="&$B$5,'Shipment Data'!$B$2:$B$1000,"<="&$B$6,'Shipment Data'!$Q$2:$Q$1000,"OK",'Shipment Data'!$D$2:$D$1000,$A42) -> 286680 | E42: =COUNTIFS('Shipment Data'!$B$2:$B$1000,">="&$B$5,'Shipment Data'!$B$2:$B$1000,"<="&$B$6,'Shipment Data'!$Q$2:$Q$1000,"OK",'Shipment Data'!$D$2:$D$1000,$A42,'Shipment Data'!$O$2:$O$1000,"No") -> 2
A43: =Masters!A11 -> DEL-KNP | B43: =Masters!B11&" - "&Masters!C11 -> Delhi - Kanpur | C43: =COUNTIFS('Shipment Data'!$B$2:$B$1000,">="&$B$5,'Shipment Data'!$B$2:$B$1000,"<="&$B$6,'Shipment Data'!$Q$2:$Q$1000,"OK",'Shipment Data'!$D$2:$D$1000,$A43) -> 4 | D43: =SUMIFS('Shipment Data'!$I$2:$I$1000,'Shipment Data'!$B$2:$B$1000,">="&$B$5,'Shipment Data'!$B$2:$B$1000,"<="&$B$6,'Shipment Data'!$Q$2:$Q$1000,"OK",'Shipment Data'!$D$2:$D$1000,$A43) -> 104895 | E43: =COUNTIFS('Shipment Data'!$B$2:$B$1000,">="&$B$5,'Shipment Data'!$B$2:$B$1000,"<="&$B$6,'Shipment Data'!$Q$2:$Q$1000,"OK",'Shipment Data'!$D$2:$D$1000,$A43,'Shipment Data'!$O$2:$O$1000,"No") -> 1
A44: =Masters!A12 -> DEL-AGR | B44: =Masters!B12&" - "&Masters!C12 -> Delhi - Agra | C44: =COUNTIFS('Shipment Data'!$B$2:$B$1000,">="&$B$5,'Shipment Data'!$B$2:$B$1000,"<="&$B$6,'Shipment Data'!$Q$2:$Q$1000,"OK",'Shipment Data'!$D$2:$D$1000,$A44) -> 3 | D44: =SUMIFS('Shipment Data'!$I$2:$I$1000,'Shipment Data'!$B$2:$B$1000,">="&$B$5,'Shipment Data'!$B$2:$B$1000,"<="&$B$6,'Shipment Data'!$Q$2:$Q$1000,"OK",'Shipment Data'!$D$2:$D$1000,$A44) -> 53984 | E44: =COUNTIFS('Shipment Data'!$B$2:$B$1000,">="&$B$5,'Shipment Data'!$B$2:$B$1000,"<="&$B$6,'Shipment Data'!$Q$2:$Q$1000,"OK",'Shipment Data'!$D$2:$D$1000,$A44,'Shipment Data'!$O$2:$O$1000,"No") -> 1
...

Sheet Shipment Data
A1: Shipment ID | B1: Ship Date | C1: Client | D1: Route Code | E1: Origin | F1: Destination | G1: Weight (kg) | H1: Rate per kg (Rs) | I1: Freight Amount (Rs) | J1: Vehicle Type | K1: Promised Delivery | L1: Actual Delivery | M1: Delivery Status | N1: Delay Days | O1: On-Time? | P1: Month | Q1: Data Check
A2: SHP-2026-0001 | B2: 46116 | C2: Apex Electronics | D2: GZB-MRT | E2: =IFERROR(VLOOKUP(D2,Masters!$A$5:$E$16,2,FALSE()),"") -> Ghaziabad | F2: =IFERROR(VLOOKUP(D2,Masters!$A$5:$E$16,3,FALSE()),"") -> Meerut | G2: 3250 | H2: =IFERROR(INDEX(Masters!$D$5:$D$16,MATCH(D2,Masters!$A$5:$A$16,0)),"") -> 1.8 | I2: =IF(OR(G2="",H2=""),"",G2*H2) -> 5850 | J2: Eicher 14ft | K2: =IF(OR(B2="",D2=""),"",IFERROR(B2+VLOOKUP(D2,Masters!$A$5:$E$16,5,FALSE()),"")) -> 46117 | L2: 46117 | M2: Delivered | N2: =IF(OR(L2="",K2=""),"",MAX(0,L2-K2)) -> 0 | O2: =IF(M2="In Transit","Pending",IF(OR(L2="",K2=""),"",IF(L2<=K2,"Yes","No"))) -> Yes | P2: =IF(B2="","",DATE(YEAR(B2),MONTH(B2),1)) -> 46113 | Q2: =IF(OR(A2="",B2="",C2="",D2="",G2=""),"Missing Field",IF(COUNTIF($A$2:$A$1000,A2)>1,"Duplicate ID",IF(G2<=0,"Invalid Weight",IF(AND(L2<>"",L2<B2),"Delivery Before Ship Date",IF(AND(M2="Delivered",L2=""),"Delivered But No Date","OK"))))) -> OK
A3: SHP-2026-0002 | B3: 46117 | C3: Shree Ganesh Traders | D3: DEL-AMD | E3: =IFERROR(VLOOKUP(D3,Masters!$A$5:$E$16,2,FALSE()),"") -> Delhi | F3: =IFERROR(VLOOKUP(D3,Masters!$A$5:$E$16,3,FALSE()),"") -> Ahmedabad | G3: 600 | H3: =IFERROR(INDEX(Masters!$D$5:$D$16,MATCH(D3,Masters!$A$5:$A$16,0)),"") -> 7.5 | I3: =IF(OR(G3="",H3=""),"",G3*H3) -> 4500 | J3: Tata Ace (Mini) | K3: =IF(OR(B3="",D3=""),"",IFERROR(B3+VLOOKUP(D3,Masters!$A$5:$E$16,5,FALSE()),"")) -> 46121 | L3: 46121 | M3: Delivered | N3: =IF(OR(L3="",K3=""),"",MAX(0,L3-K3)) -> 0 | O3: =IF(M3="In Transit","Pending",IF(OR(L3="",K3=""),"",IF(L3<=K3,"Yes","No"))) -> Yes | P3: =IF(B3="","",DATE(YEAR(B3),MONTH(B3),1)) -> 46113 | Q3: =IF(OR(A3="",B3="",C3="",D3="",G3=""),"Missing Field",IF(COUNTIF($A$2:$A$1000,A3)>1,"Duplicate ID",IF(G3<=0,"Invalid Weight",IF(AND(L3<>"",L3<B3),"Delivery Before Ship Date",IF(AND(M3="Delivered",L3=""),"Delivered But No Date","OK"))))) -> OK
A4: SHP-2026-0003 | B4: 46123 | C4: Shree Ganesh Traders | D4: DEL-LKO | E4: =IFERROR(VLOOKUP(D4,Masters!$A$5:$E$16,2,FALSE()),"") -> Delhi | F4: =IFERROR(VLOOKUP(D4,Masters!$A$5:$E$16,3,FALSE()),"") -> Lucknow | G4: 6710 | H4: =IFERROR(INDEX(Masters!$D$5:$D$16,MATCH(D4,Masters!$A$5:$A$16,0)),"") -> 5.2 | I4: =IF(OR(G4="",H4=""),"",G4*H4) -> 34892 | J4: Container 20ft | K4: =IF(OR(B4="",D4=""),"",IFERROR(B4+VLOOKUP(D4,Masters!$A$5:$E$16,5,FALSE()),"")) -> 46126 | L4: 46129 | M4: Delivered | N4: =IF(OR(L4="",K4=""),"",MAX(0,L4-K4)) -> 3 | O4: =IF(M4="In Transit","Pending",IF(OR(L4="",K4=""),"",IF(L4<=K4,"Yes","No"))) -> No | P4: =IF(B4="","",DATE(YEAR(B4),MONTH(B4),1)) -> 46113 | Q4: =IF(OR(A4="",B4="",C4="",D4="",G4=""),"Missing Field",IF(COUNTIF($A$2:$A$1000,A4)>1,"Duplicate ID",IF(G4<=0,"Invalid Weight",IF(AND(L4<>"",L4<B4),"Delivery Before Ship Date",IF(AND(M4="Delivered",L4=""),"Delivered But No Date","OK"))))) -> OK
A5: SHP-2026-0004 | B5: 46124 | C5: Shree Ganesh Traders | D5: DEL-CCU | E5: =IFERROR(VLOOKUP(D5,Masters!$A$5:$E$16,2,FALSE()),"") -> Delhi | F5: =IFERROR(VLOOKUP(D5,Masters!$A$5:$E$16,3,FALSE()),"") -> Kolkata | G5: 2560 | H5: =IFERROR(INDEX(Masters!$D$5:$D$16,MATCH(D5,Masters!$A$5:$A$16,0)),"") -> 12 | I5: =IF(OR(G5="",H5=""),"",G5*H5) -> 30720 | J5: Eicher 14ft | K5: =IF(OR(B5="",D5=""),"",IFERROR(B5+VLOOKUP(D5,Masters!$A$5:$E$16,5,FALSE()),"")) -> 46131 | L5: 46136 | M5: Delivered | N5: =IF(OR(L5="",K5=""),"",MAX(0,L5-K5)) -> 5 | O5: =IF(M5="In Transit","Pending",IF(OR(L5="",K5=""),"",IF(L5<=K5,"Yes","No"))) -> No | P5: =IF(B5="","",DATE(YEAR(B5),MONTH(B5),1)) -> 46113 | Q5: =IF(OR(A5="",B5="",C5="",D5="",G5=""),"Missing Field",IF(COUNTIF($A$2:$A$1000,A5)>1,"Duplicate ID",IF(G5<=0,"Invalid Weight",IF(AND(L5<>"",L5<B5),"Delivery Before Ship Date",IF(AND(M5="Delivered",L5=""),"Delivered But No Date","OK"))))) -> OK
A6: SHP-2026-0005 | B6: 46124 | C6: Apex Electronics | D6: DEL-BOM | E6: =IFERROR(VLOOKUP(D6,Masters!$A$5:$E$16,2,FALSE()),"") -> Delhi | F6: =IFERROR(VLOOKUP(D6,Masters!$A$5:$E$16,3,FALSE()),"") -> Mumbai | G6: 2800 | H6: =IFERROR(INDEX(Masters!$D$5:$D$16,MATCH(D6,Masters!$A$5:$A$16,0)),"") -> 9.5 | I6: =IF(OR(G6="",H6=""),"",G6*H6) -> 26600 | J6: Eicher 14ft | K6: =IF(OR(B6="",D6=""),"",IFERROR(B6+VLOOKUP(D6,Masters!$A$5:$E$16,5,FALSE()),"")) -> 46130 | L6: 46130 | M6: Delivered | N6: =IF(OR(L6="",K6=""),"",MAX(0,L6-K6)) -> 0 | O6: =IF(M6="In Transit","Pending",IF(OR(L6="",K6=""),"",IF(L6<=K6,"Yes","No"))) -> Yes | P6: =IF(B6="","",DATE(YEAR(B6),MONTH(B6),1)) -> 46113 | Q6: =IF(OR(A6="",B6="",C6="",D6="",G6=""),"Missing Field",IF(COUNTIF($A$2:$A$1000,A6)>1,"Duplicate ID",IF(G6<=0,"Invalid Weight",IF(AND(L6<>"",L6<B6),"Delivery Before Ship Date",IF(AND(M6="Delivered",L6=""),"Delivered But No Date","OK"))))) -> OK
A7: SHP-2026-0006 | B7: 46127 | C7: Bharat Auto Components | D7: DEL-KNP | E7: =IFERROR(VLOOKUP(D7,Masters!$A$5:$E$16,2,FALSE()),"") -> Delhi | F7: =IFERROR(VLOOKUP(D7,Masters!$A$5:$E$16,3,FALSE()),"") -> Kanpur | G7: 1370 | H7: =IFERROR(INDEX(Masters!$D$5:$D$16,MATCH(D7,Masters!$A$5:$A$16,0)),"") -> 4.5 | I7: =IF(OR(G7="",H7=""),"",G7*H7) -> 6165 | J7: Tata 407 | K7: =IF(OR(B7="",D7=""),"",IFERROR(B7+VLOOKUP(D7,Masters!$A$5:$E$16,5,FALSE()),"")) -> 46130 | L7: 46130 | M7: Delivered | N7: =IF(OR(L7="",K7=""),"",MAX(0,L7-K7)) -> 0 | O7: =IF(M7="In Transit","Pending",IF(OR(L7="",K7=""),"",IF(L7<=K7,"Yes","No"))) -> Yes | P7: =IF(B7="","",DATE(YEAR(B7),MONTH(B7),1)) -> 46113 | Q7: =IF(OR(A7="",B7="",C7="",D7="",G7=""),"Missing Field",IF(COUNTIF($A$2:$A$1000,A7)>1,"Duplicate ID",IF(G7<=0,"Invalid Weight",IF(AND(L7<>"",L7<B7),"Delivery Before Ship Date",IF(AND(M7="Delivered",L7=""),"Delivered But No Date","OK"))))) -> OK
A8: SHP-2026-0007 | B8: 46127 | C8: Sharma Agro Foods | D8: DEL-AMD | E8: =IFERROR(VLOOKUP(D8,Masters!$A$5:$E$16,2,FALSE()),"") -> Delhi | F8: =IFERROR(VLOOKUP(D8,Masters!$A$5:$E$16,3,FALSE()),"") -> Ahmedabad | G8: 2630 | H8: =IFERROR(INDEX(Masters!$D$5:$D$16,MATCH(D8,Masters!$A$5:$A$16,0)),"") -> 7.5 | I8: =IF(OR(G8="",H8=""),"",G8*H8) -> 19725 | J8: Eicher 14ft | K8: =IF(OR(B8="",D8=""),"",IFERROR(B8+VLOOKUP(D8,Masters!$A$5:$E$16,5,FALSE()),"")) -> 46131 | L8: 46131 | M8: Delivered | N8: =IF(OR(L8="",K8=""),"",MAX(0,L8-K8)) -> 0 | O8: =IF(M8="In Transit","Pending",IF(OR(L8="",K8=""),"",IF(L8<=K8,"Yes","No"))) -> Yes | P8: =IF(B8="","",DATE(YEAR(B8),MONTH(B8),1)) -> 46113 | Q8: =IF(OR(A8="",B8="",C8="",D8="",G8=""),"Missing Field",IF(COUNTIF($A$2:$A$1000,A8)>1,"Duplicate ID",IF(G8<=0,"Invalid Weight",IF(AND(L8<>"",L8<B8),"Delivery Before Ship Date",IF(AND(M8="Delivered",L8=""),"Delivered But No Date","OK"))))) -> OK
A9: SHP-2026-0008 | B9: 46127 | C9: Shree Ganesh Traders | D9: GZB-MRT | E9: =IFERROR(VLOOKUP(D9,Masters!$A$5:$E$16,2,FALSE()),"") -> Ghaziabad | F9: =IFERROR(VLOOKUP(D9,Masters!$A$5:$E$16,3,FALSE()),"") -> Meerut | G9: 2810 | H9: =IFERROR(INDEX(Masters!$D$5:$D$16,MATCH(D9,Masters!$A$5:$A$16,0)),"") -> 1.8 | I9: =IF(OR(G9="",H9=""),"",G9*H9) -> 5058 | J9: Eicher 14ft | K9: =IF(OR(B9="",D9=""),"",IFERROR(B9+VLOOKUP(D9,Masters!$A$5:$E$16,5,FALSE()),"")) -> 46128 | L9: 46130 | M9: Delivered | N9: =IF(OR(L9="",K9=""),"",MAX(0,L9-K9)) -> 2 | O9: =IF(M9="In Transit","Pending",IF(OR(L9="",K9=""),"",IF(L9<=K9,"Yes","No"))) -> No | P9: =IF(B9="","",DATE(YEAR(B9),MONTH(B9),1)) -> 46113 | Q9: =IF(OR(A9="",B9="",C9="",D9="",G9=""),"Missing Field",IF(COUNTIF($A$2:$A$1000,A9)>1,"Duplicate ID",IF(G9<=0,"Invalid Weight",IF(AND(L9<>"",L9<B9),"Delivery Before Ship Date",IF(AND(M9="Delivered",L9=""),"Delivered But No Date","OK"))))) -> OK
A10: SHP-2026-0009 | B10: 46129 | C10: Krishna Steel Works | D10: DEL-AMD | E10: =IFERROR(VLOOKUP(D10,Masters!$A$5:$E$16,2,FALSE()),"") -> Delhi | F10: =IFERROR(VLOOKUP(D10,Masters!$A$5:$E$16,3,FALSE()),"") -> Ahmedabad | G10: 5770 | H10: =IFERROR(INDEX(Masters!$D$5:$D$16,MATCH(D10,Masters!$A$5:$A$16,0)),"") -> 7.5 | I10: =IF(OR(G10="",H10=""),"",G10*H10) -> 43275 | J10: Container 20ft | K10: =IF(OR(B10="",D10=""),"",IFERROR(B10+VLOOKUP(D10,Masters!$A$5:$E$16,5,FALSE()),"")) -> 46133 | L10: 46132 | M10: Delivered | N10: =IF(OR(L10="",K10=""),"",MAX(0,L10-K10)) -> 0 | O10: =IF(M10="In Transit","Pending",IF(OR(L10="",K10=""),"",IF(L10<=K10,"Yes","No"))) -> Yes | P10: =IF(B10="","",DATE(YEAR(B10),MONTH(B10),1)) -> 46113 | Q10: =IF(OR(A10="",B10="",C10="",D10="",G10=""),"Missing Field",IF(COUNTIF($A$2:$A$1000,A10)>1,"Duplicate ID",IF(G10<=0,"Invalid Weight",IF(AND(L10<>"",L10<B10),"Delivery Before Ship Date",IF(AND(M10="Delivered",L10=""),"Delivered But No Date","OK"))))) -> OK
A11: SHP-2026-0010 | B11: 46131 | C11: Metro Fabrics Pvt Ltd | D11: DEL-DED | E11: =IFERROR(VLOOKUP(D11,Masters!$A$5:$E$16,2,FALSE()),"") -> Delhi | F11: =IFERROR(VLOOKUP(D11,Masters!$A$5:$E$16,3,FALSE()),"") -> Dehradun | G11: 5870 | H11: =IFERROR(INDEX(Masters!$D$5:$D$16,MATCH(D11,Masters!$A$5:$A$16,0)),"") -> 4 | I11: =IF(OR(G11="",H11=""),"",G11*H11) -> 23480 | J11: Container 20ft | K11: =IF(OR(B11="",D11=""),"",IFERROR(B11+VLOOKUP(D11,Masters!$A$5:$E$16,5,FALSE()),"")) -> 46133 | L11: 46135 | M11: Delivered | N11: =IF(OR(L11="",K11=""),"",MAX(0,L11-K11)) -> 2 | O11: =IF(M11="In Transit","Pending",IF(OR(L11="",K11=""),"",IF(L11<=K11,"Yes","No"))) -> No | P11: =IF(B11="","",DATE(YEAR(B11),MONTH(B11),1)) -> 46113 | Q11: =IF(OR(A11="",B11="",C11="",D11="",G11=""),"Missing Field",IF(COUNTIF($A$2:$A$1000,A11)>1,"Duplicate ID",IF(G11<=0,"Invalid Weight",IF(AND(L11<>"",L11<B11),"Delivery Before Ship Date",IF(AND(M11="Delivered",L11=""),"Delivered But No Date","OK"))))) -> OK
A12: SHP-2026-0011 | B12: 46131 | C12: Sharma Agro Foods | D12: DEL-BPL | E12: =IFERROR(VLOOKUP(D12,Masters!$A$5:$E$16,2,FALSE()),"") -> Delhi | F12: =IFERROR(VLOOKUP(D12,Masters!$A$5:$E$16,3,FALSE()),"") -> Bhopal | H12: =IFERROR(INDEX(Masters!$D$5:$D$16,MATCH(D12,Masters!$A$5:$A$16,0)),"") -> 8 | I12: =IF(OR(G12="",H12=""),"",G12*H12) | J12: Container 20ft | K12: =IF(OR(B12="",D12=""),"",IFERROR(B12+VLOOKUP(D12,Masters!$A$5:$E$16,5,FALSE()),"")) -> 46136 | L12: 46137 | M12: Delivered | N12: =IF(OR(L12="",K12=""),"",MAX(0,L12-K12)) -> 1 | O12: =IF(M12="In Transit","Pending",IF(OR(L12="",K12=""),"",IF(L12<=K12,"Yes","No"))) -> No | P12: =IF(B12="","",DATE(YEAR(B12),MONTH(B12),1)) -> 46113 | Q12: =IF(OR(A12="",B12="",C12="",D12="",G12=""),"Missing Field",IF(COUNTIF($A$2:$A$1000,A12)>1,"Duplicate ID",IF(G12<=0,"Invalid Weight",IF(AND(L12<>"",L12<B12),"Delivery Before Ship Date",IF(AND(M12="Delivered",L12=""),"Delivered But No Date","OK"))))) -> Missing Field
A13: SHP-2026-0012 | B13: 46132 | C13: Kailash Pharma | D13: GZB-MRT | E13: =IFERROR(VLOOKUP(D13,Masters!$A$5:$E$16,2,FALSE()),"") -> Ghaziabad | F13: =IFERROR(VLOOKUP(D13,Masters!$A$5:$E$16,3,FALSE()),"") -> Meerut | G13: 9800 | H13: =IFERROR(INDEX(Masters!$D$5:$D$16,MATCH(D13,Masters!$A$5:$A$16,0)),"") -> 1.8 | I13: =IF(OR(G13="",H13=""),"",G13*H13) -> 17640 | J13: Trailer 32ft | K13: =IF(OR(B13="",D13=""),"",IFERROR(B13+VLOOKUP(D13,Masters!$A$5:$E$16,5,FALSE()),"")) -> 46133 | L13: 46133 | M13: Delivered | N13: =IF(OR(L13="",K13=""),"",MAX(0,L13-K13)) -> 0 | O13: =IF(M13="In Transit","Pending",IF(OR(L13="",K13=""),"",IF(L13<=K13,"Yes","No"))) -> Yes | P13: =IF(B13="","",DATE(YEAR(B13),MONTH(B13),1)) -> 46113 | Q13: =IF(OR(A13="",B13="",C13="",D13="",G13=""),"Missing Field",IF(COUNTIF($A$2:$A$1000,A13)>1,"Duplicate ID",IF(G13<=0,"Invalid Weight",IF(AND(L13<>"",L13<B13),"Delivery Before Ship Date",IF(AND(M13="Delivered",L13=""),"Delivered But No Date","OK"))))) -> OK
A14: SHP-2026-0013 | B14: 46135 | C14: Metro Fabrics Pvt Ltd | D14: DEL-JPR | E14: =IFERROR(VLOOKUP(D14,Masters!$A$5:$E$16,2,FALSE()),"") -> Delhi | F14: =IFERROR(VLOOKUP(D14,Masters!$A$5:$E$16,3,FALSE()),"") -> Jaipur | G14: 5570 | H14: =IFERROR(INDEX(Masters!$D$5:$D$16,MATCH(D14,Masters!$A$5:$A$16,0)),"") -> 3.5 | I14: =IF(OR(G14="",H14=""),"",G14*H14) -> 19495 | J14: Container 20ft | K14: =IF(OR(B14="",D14=""),"",IFERROR(B14+VLOOKUP(D14,Masters!$A$5:$E$16,5,FALSE()),"")) -> 46137 | L14: 46136 | M14: Delivered | N14: =IF(OR(L14="",K14=""),"",MAX(0,L14-K14)) -> 0 | O14: =IF(M14="In Transit","Pending",IF(OR(L14="",K14=""),"",IF(L14<=K14,"Yes","No"))) -> Yes | P14: =IF(B14="","",DATE(YEAR(B14),MONTH(B14),1)) -> 46113 | Q14: =IF(OR(A14="",B14="",C14="",D14="",G14=""),"Missing Field",IF(COUNTIF($A$2:$A$1000,A14)>1,"Duplicate ID",IF(G14<=0,"Invalid Weight",IF(AND(L14<>"",L14<B14),"Delivery Before Ship Date",IF(AND(M14="Delivered",L14=""),"Delivered But No Date","OK"))))) -> OK
A15: SHP-2026-0014 | B15: 46135 | C15: Apex Electronics | D15: DEL-CHD | E15: =IFERROR(VLOOKUP(D15,Masters!$A$5:$E$16,2,FALSE()),"") -> Delhi | F15: =IFERROR(VLOOKUP(D15,Masters!$A$5:$E$16,3,FALSE()),"") -> Chandigarh | G15: 1970 | H15: =IFERROR(INDEX(Masters!$D$5:$D$16,MATCH(D15,Masters!$A$5:$A$16,0)),"") -> 3 | I15: =IF(OR(G15="",H15=""),"",G15*H15) -> 5910 | J15: Tata 407 | K15: =IF(OR(B15="",D15=""),"",IFERROR(B15+VLOOKUP(D15,Masters!$A$5:$E$16,5,FALSE()),"")) -> 46137 | L15: 46136 | M15: Delivered | N15: =IF(OR(L15="",K15=""),"",MAX(0,L15-K15)) -> 0 | O15: =IF(M15="In Transit","Pending",IF(OR(L15="",K15=""),"",IF(L15<=K15,"Yes","No"))) -> Yes | P15: =IF(B15="","",DATE(YEAR(B15),MONTH(B15),1)) -> 46113 | Q15: =IF(OR(A15="",B15="",C15="",D15="",G15=""),"Missing Field",IF(COUNTIF($A$2:$A$1000,A15)>1,"Duplicate ID",IF(G15<=0,"Invalid Weight",IF(AND(L15<>"",L15<B15),"Delivery Before Ship Date",IF(AND(M15="Delivered",L15=""),"Delivered But No Date","OK"))))) -> OK
A16: SHP-2026-0015 | B16: 46135 | C16: Shree Ganesh Traders | D16: DEL-JPR | E16: =IFERROR(VLOOKUP(D16,Masters!$A$5:$E$16,2,FALSE()),"") -> Delhi | F16: =IFERROR(VLOOKUP(D16,Masters!$A$5:$E$16,3,FALSE()),"") -> Jaipur | G16: 10510 | H16: =IFERROR(INDEX(Masters!$D$5:$D$16,MATCH(D16,Masters!$A$5:$A$16,0)),"") -> 3.5 | I16: =IF(OR(G16="",H16=""),"",G16*H16) -> 36785 | J16: Trailer 32ft | K16: =IF(OR(B16="",D16=""),"",IFERROR(B16+VLOOKUP(D16,Masters!$A$5:$E$16,5,FALSE()),"")) -> 46137 | L16: 46137 | M16: Delivered | N16: =IF(OR(L16="",K16=""),"",MAX(0,L16-K16)) -> 0 | O16: =IF(M16="In Transit","Pending",IF(OR(L16="",K16=""),"",IF(L16<=K16,"Yes","No"))) -> Yes | P16: =IF(B16="","",DATE(YEAR(B16),MONTH(B16),1)) -> 46113 | Q16: =IF(OR(A16="",B16="",C16="",D16="",G16=""),"Missing Field",IF(COUNTIF($A$2:$A$1000,A16)>1,"Duplicate ID",IF(G16<=0,"Invalid Weight",IF(AND(L16<>"",L16<B16),"Delivery Before Ship Date",IF(AND(M16="Delivered",L16=""),"Delivered But No Date","OK"))))) -> OK
A17: SHP-2026-0016 | B17: 46136 | C17: Metro Fabrics Pvt Ltd | D17: DEL-CCU | E17: =IFERROR(VLOOKUP(D17,Masters!$A$5:$E$16,2,FALSE()),"") -> Delhi | F17: =IFERROR(VLOOKUP(D17,Masters!$A$5:$E$16,3,FALSE()),"") -> Kolkata | G17: 6440 | H17: =IFERROR(INDEX(Masters!$D$5:$D$16,MATCH(D17,Masters!$A$5:$A$16,0)),"") -> 12 | I17: =IF(OR(G17="",H17=""),"",G17*H17) -> 77280 | J17: Container 20ft | K17: =IF(OR(B17="",D17=""),"",IFERROR(B17+VLOOKUP(D17,Masters!$A$5:$E$16,5,FALSE()),"")) -> 46143 | L17: 46143 | M17: Delivered | N17: =IF(OR(L17="",K17=""),"",MAX(0,L17-K17)) -> 0 | O17: =IF(M17="In Transit","Pending",IF(OR(L17="",K17=""),"",IF(L17<=K17,"Yes","No"))) -> Yes | P17: =IF(B17="","",DATE(YEAR(B17),MONTH(B17),1)) -> 46113 | Q17: =IF(OR(A17="",B17="",C17="",D17="",G17=""),"Missing Field",IF(COUNTIF($A$2:$A$1000,A17)>1,"Duplicate ID",IF(G17<=0,"Invalid Weight",IF(AND(L17<>"",L17<B17),"Delivery Before Ship Date",IF(AND(M17="Delivered",L17=""),"Delivered But No Date","OK"))))) -> OK
